Workbook

Sheet Dashboard
B1: 主升浪信号跟踪 KPI 仪表盘
B2: 跟踪天数 | D2: 观察池数量（最新） | F2: 买点提示（最新） | H2: 平均综合分（最新） | J2: 平均涨跌幅（最新） | L2: 上涨家数（最新）
B3: =COUNTA(Summary!A2:A4) -> 3 | D3: =Summary!B4 -> 36 | F3: =Summary!F4 -> 3 | H3: =Summary!C4 -> 72.866667 | J3: =Summary!D4 -> 3.0845745 | L3: =Summary!E4 -> 25
B7: ="今日买点提示（"&TEXT(Summary!$A$4,"yyyy-mm-dd")&"）" -> 今日买点提示（2026-08-06）
B8: 状态 | C8: 名称 | E8: 综合分 | G8: 提示
B9: =IFERROR(INDEX(Data!$H:$H,SMALL(Data!$N$2:$N$1000,1)),"") -> T1确认买点 | C9: =IFERROR(INDEX(Data!$D:$D,SMALL(Data!$N$2:$N$1000,1)),"") -> 紫金矿业 | E9: =IFERROR(INDEX(Data!$E:$E,SMALL(Data!$N$2:$N$1000,1)),"") -> 81.8 | G9: =IFERROR(INDEX(Data!$I:$I,SMALL(Data!$N$2:$N$1000,1)),"") -> 买点1：明日开盘买入（信号日收盘 34.10，止损-5%）
B10: =IFERROR(INDEX(Data!$H:$H,SMALL(Data!$N$2:$N$1000,2)),"") -> 回踩低吸 | C10: =IFERROR(INDEX(Data!$D:$D,SMALL(Data!$N$2:$N$1000,2)),"") -> 桂冠电力 | E10: =IFERROR(INDEX(Data!$E:$E,SMALL(Data!$N$2:$N$1000,2)),"") -> 74.5 | G10: =IFERROR(INDEX(Data!$I:$I,SMALL(Data!$N$2:$N$1000,2)),"") -> 买点2：MA10(10.79)附近缩量企稳，可低吸
B11: =IFERROR(INDEX(Data!$H:$H,SMALL(Data!$N$2:$N$1000,3)),"") -> T1确认买点 | C11: =IFERROR(INDEX(Data!$D:$D,SMALL(Data!$N$2:$N$1000,3)),"") -> 金诚信 | E11: =IFERROR(INDEX(Data!$E:$E,SMALL(Data!$N$2:$N$1000,3)),"") -> 73.6 | G11: =IFERROR(INDEX(Data!$I:$I,SMALL(Data!$N$2:$N$1000,3)),"") -> 买点1：明日开盘买入（信号日收盘 78.68，止损-5%）
B32: 主升浪信号跟踪 KPI 仪表盘（数据源: output/reports/主升浪跟踪_2026-08-04/05/06.csv + output/state/mainrise_positions.csv；涨跌幅/10日涨幅为百分数，如 8.83 即 8.83%）
B33: 买点明细=最新日观察池内 T0/T1/回踩低吸 且 10日涨幅<80%（防追高）；持仓收益=每日收盘/买入价-1（买入价 32.12，来源 positions.csv）；免责：研究线索，不构成投资建议

Sheet Summary
A1: 日期 | B1: 观察池数量 | C1: 平均综合分 | D1: 平均涨跌幅(%) | E1: 上涨家数 | F1: 买点提示 | G1: 破位家数 | H1: 空头家数 | I1: 多头持有家数 | J1: 新增信号数 | L1: 日期（文本）
A2: =DATE(2026,8,4) -> 46238 | B2: =COUNTIFS(Data!$A$2:$A$1000,$A2,Data!$B$2:$B$1000,"观察池") -> 36 | C2: =IFERROR(AVERAGEIFS(Data!$E$2:$E$1000,Data!$A$2:$A$1000,$A2,Data!$B$2:$B$1000,"观察池"),0) -> 72.866667 | D2: =IFERROR(AVERAGEIFS(Data!$G$2:$G$1000,Data!$A$2:$A$1000,$A2,Data!$B$2:$B$1000,"观察池"),0) -> 4.6637446 | E2: =COUNTIFS(Data!$A$2:$A$1000,$A2,Data!$B$2:$B$1000,"观察池",Data!$G$2:$G$1000,">0") -> 30 | F2: =COUNTIFS(Data!$A$2:$A$1000,$A2,Data!$B$2:$B$1000,"观察池",Data!$H$2:$H$1000,"T1确认买点",Data!$M$2:$M$1000,"<80")+COUNTIFS(Data!$A$2:$A$1000,$A2,Data!$B$2:$B$1000,"观察池",Data!$H$2:$H$1000,"T0新信号",Data!$M$2:$M$1000,"<80")+COUNTIFS(Data!$A$2:$A$1000,$A2,Data!$B$2:$B$1000,"观察池",Data!$H$2:$H$1000,"回踩低吸",Data!$M$2:$M$1000,"<80") -> 5 | G2: =COUNTIFS(Data!$A$2:$A$1000,$A2,Data!$B$2:$B$1000,"观察池",Data!$H$2:$H$1000,"破位") -> 21 | H2: =COUNTIFS(Data!$A$2:$A$1000,$A2,Data!$B$2:$B$1000,"观察池",Data!$H$2:$H$1000,"空头") -> 6 | I2: =COUNTIFS(Data!$A$2:$A$1000,$A2,Data!$B$2:$B$1000,"观察池",Data!$H$2:$H$1000,"多头持有") -> 2 | J2: =COUNTIFS(Data!$A$2:$A$1000,$A2,Data!$B$2:$B$1000,"新信号") -> 0 | L2: =TEXT(A2,"yyyy-mm-dd") -> 2026-08-04
A3: =DATE(2026,8,5) -> 46239 | B3: =COUNTIFS(Data!$A$2:$A$1000,$A3,Data!$B$2:$B$1000,"观察池") -> 36 | C3: =IFERROR(AVERAGEIFS(Data!$E$2:$E$1000,Data!$A$2:$A$1000,$A3,Data!$B$2:$B$1000,"观察池"),0) -> 72.866667 | D3: =IFERROR(AVERAGEIFS(Data!$G$2:$G$1000,Data!$A$2:$A$1000,$A3,Data!$B$2:$B$1000,"观察池"),0) -> 5.2695033 | E3: =COUNTIFS(Data!$A$2:$A$1000,$A3,Data!$B$2:$B$1000,"观察池",Data!$G$2:$G$1000,">0") -> 30 | F3: =COUNTIFS(Data!$A$2:$A$1000,$A3,Data!$B$2:$B$1000,"观察池",Data!$H$2:$H$1000,"T1确认买点",Data!$M$2:$M$1000,"<80")+COUNTIFS(Data!$A$2:$A$1000,$A3,Data!$B$2:$B$1000,"观察池",Data!$H$2:$H$1000,"T0新信号",Data!$M$2:$M$1000,"<80")+COUNTIFS(Data!$A$2:$A$1000,$A3,Data!$B$2:$B$1000,"观察池",Data!$H$2:$H$1000,"回踩低吸",Data!$M$2:$M$1000,"<80") -> 3 | G3: =COUNTIFS(Data!$A$2:$A$1000,$A3,Data!$B$2:$B$1000,"观察池",Data!$H$2:$H$1000,"破位") -> 18 | H3: =COUNTIFS(Data!$A$2:$A$1000,$A3,Data!$B$2:$B$1000,"观察池",Data!$H$2:$H$1000,"空头") -> 9 | I3: =COUNTIFS(Data!$A$2:$A$1000,$A3,Data!$B$2:$B$1000,"观察池",Data!$H$2:$H$1000,"多头持有") -> 5 | J3: =COUNTIFS(Data!$A$2:$A$1000,$A3,Data!$B$2:$B$1000,"新信号") -> 83 | L3: =TEXT(A3,"yyyy-mm-dd") -> 2026-08-05
A4: =DATE(2026,8,6) -> 46240 | B4: =COUNTIFS(Data!$A$2:$A$1000,$A4,Data!$B$2:$B$1000,"观察池") -> 36 | C4: =IFERROR(AVERAGEIFS(Data!$E$2:$E$1000,Data!$A$2:$A$1000,$A4,Data!$B$2:$B$1000,"观察池"),0) -> 72.866667 | D4: =IFERROR(AVERAGEIFS(Data!$G$2:$G$1000,Data!$A$2:$A$1000,$A4,Data!$B$2:$B$1000,"观察池"),0) -> 3.0845745 | E4: =COUNTIFS(Data!$A$2:$A$1000,$A4,Data!$B$2:$B$1000,"观察池",Data!$G$2:$G$1000,">0") -> 25 | F4: =COUNTIFS(Data!$A$2:$A$1000,$A4,Data!$B$2:$B$1000,"观察池",Data!$H$2:$H$1000,"T1确认买点",Data!$M$2:$M$1000,"<80")+COUNTIFS(Data!$A$2:$A$1000,$A4,Data!$B$2:$B$1000,"观察池",Data!$H$2:$H$1000,"T0新信号",Data!$M$2:$M$1000,"<80")+COUNTIFS(Data!$A$2:$A$1000,$A4,Data!$B$2:$B$1000,"观察池",Data!$H$2:$H$1000,"回踩低吸",Data!$M$2:$M$1000,"<80") -> 3 | G4: =COUNTIFS(Data!$A$2:$A$1000,$A4,Data!$B$2:$B$1000,"观察池",Data!$H$2:$H$1000,"破位") -> 10 | H4: =COUNTIFS(Data!$A$2:$A$1000,$A4,Data!$B$2:$B$1000,"观察池",Data!$H$2:$H$1000,"空头") -> 15 | I4: =COUNTIFS(Data!$A$2:$A$1000,$A4,Data!$B$2:$B$1000,"观察池",Data!$H$2:$H$1000,"多头持有") -> 6 | J4: =COUNTIFS(Data!$A$2:$A$1000,$A4,Data!$B$2:$B$1000,"新信号") -> 0 | L4: =TEXT(A4,"yyyy-mm-dd") -> 2026-08-06
A5: 状态分布（观察池，按日）
A6: 状态 | B6: =$A$2 -> 46238 | C6: =$A$3 -> 46239 | D6: =$A$4 -> 46240
A7: 空头 | B7: =COUNTIFS(Data!$A$2:$A$1000,$A$2,Data!$B$2:$B$1000,"观察池",Data!$H$2:$H$1000,$A7) -> 6 | C7: =COUNTIFS(Data!$A$2:$A$1000,$A$3,Data!$B$2:$B$1000,"观察池",Data!$H$2:$H$1000,$A7) -> 9 | D7: =COUNTIFS(Data!$A$2:$A$1000,$A$4,Data!$B$2:$B$1000,"观察池",Data!$H$2:$H$1000,$A7) -> 15
A8: 破位 | B8: =COUNTIFS(Data!$A$2:$A$1000,$A$2,Data!$B$2:$B$1000,"观察池",Data!$H$2:$H$1000,$A8) -> 21 | C8: =COUNTIFS(Data!$A$2:$A$1000,$A$3,Data!$B$2:$B$1000,"观察池",Data!$H$2:$H$1000,$A8) -> 18 | D8: =COUNTIFS(Data!$A$2:$A$1000,$A$4,Data!$B$2:$B$1000,"观察池",Data!$H$2:$H$1000,$A8) -> 10
A9: 多头持有 | B9: =COUNTIFS(Data!$A$2:$A$1000,$A$2,Data!$B$2:$B$1000,"观察池",Data!$H$2:$H$1000,$A9) -> 2 | C9: =COUNTIFS(Data!$A$2:$A$1000,$A$3,Data!$B$2:$B$1000,"观察池",Data!$H$2:$H$1000,$A9) -> 5 | D9: =COUNTIFS(Data!$A$2:$A$1000,$A$4,Data!$B$2:$B$1000,"观察池",Data!$H$2:$H$1000,$A9) -> 6
A10: 回踩低吸 | B10: =COUNTIFS(Data!$A$2:$A$1000,$A$2,Data!$B$2:$B$1000,"观察池",Data!$H$2:$H$1000,$A10) -> 5 | C10: =COUNTIFS(Data!$A$2:$A$1000,$A$3,Data!$B$2:$B$1000,"观察池",Data!$H$2:$H$1000,$A10) -> 1 | D10: =COUNTIFS(Data!$A$2:$A$1000,$A$4,Data!$B$2:$B$1000,"观察池",Data!$H$2:$H$1000,$A10) -> 1
A11: 多头回踩 | B11: =COUNTIFS(Data!$A$2:$A$1000,$A$2,Data!$B$2:$B$1000,"观察池",Data!$H$2:$H$1000,$A11) -> 1 | C11: =COUNTIFS(Data!$A$2:$A$1000,$A$3,Data!$B$2:$B$1000,"观察池",Data!$H$2:$H$1000,$A11) -> 0 | D11: =COUNTIFS(Data!$A$2:$A$1000,$A$4,Data!$B$2:$B$1000,"观察池",Data!$H$2:$H$1000,$A11) -> 1
A12: T1确认买点 | B12: =COUNTIFS(Data!$A$2:$A$1000,$A$2,Data!$B$2:$B$1000,"观察池",Data!$H$2:$H$1000,$A12) -> 0 | C12: =COUNTIFS(Data!$A$2:$A$1000,$A$3,Data!$B$2:$B$1000,"观察池",Data!$H$2:$H$1000,$A12) -> 0 | D12: =COUNTIFS(Data!$A$2:$A$1000,$A$4,Data!$B$2:$B$1000,"观察池",Data!$H$2:$H$1000,$A12) -> 3
A13: T0新信号 | B13: =COUNTIFS(Data!$A$2:$A$1000,$A$2,Data!$B$2:$B$1000,"观察池",Data!$H$2:$H$1000,$A13) -> 1 | C13: =COUNTIFS(Data!$A$2:$A$1000,$A$3,Data!$B$2:$B$1000,"观察池",Data!$H$2:$H$1000,$A13) -> 3 | D13: =COUNTIFS(Data!$A$2:$A$1000,$A$4,Data!$B$2:$B$1000,"观察池",Data!$H$2:$H$1000,$A13) -> 0
A14: 数据源: output/reports/主升浪跟踪_2026-08-04/05/06.csv（观察池36只 + 08-05全市场新信号83只）；涨跌幅/10日涨幅为百分数（8.83 即 8.83%）；买点提示=观察池中 T0/T1/回踩低吸 且 10日涨幅<80%（防追高）。
A16: 图表辅助数据（持仓收益 / Top10 分档）
O17: 紫金收盘 | P17: 持仓盈亏%
O18: =SUMIFS(Data!$F$2:$F$1000,Data!$A$2:$A$1000,$A$2,Data!$C$2:$C$1000,"601899") -> 32.12 | P18: =IFERROR((O18/$P$23-1)*100,"") -> 0
O19: =SUMIFS(Data!$F$2:$F$1000,Data!$A$2:$A$1000,$A$3,Data!$C$2:$C$1000,"601899") -> 34.1 | P19: =IFERROR((O19/$P$23-1)*100,"") -> 6.1643836
O20: =SUMIFS(Data!$F$2:$F$1000,Data!$A$2:$A$1000,$A$4,Data!$C$2:$C$1000,"601899") -> 34.5 | P20: =IFERROR((O20/$P$23-1)*100,"") -> 7.4097136
P22: 买入价(紫金矿业)
P23: 32.12
P24: 来源: output/state/mainrise_positions.csv（2026-08-04 回踩低吸建仓，当前 active）

Sheet Watch
A1: 代码 | B1: 名称 | C1: 综合分 | D1: 收盘 | E1: 涨跌幅(%) | F1: 状态 | G1: 提示 | H1: >80 | I1: 75-80
A2: 000657 | B2: 中钨高新 | C2: 86.3 | D2: 62.5 | E2: 8.8281386 | F2: 空头 | G2: 均线未多头，观望 | H2: =IF($C2>80,$C2,"") -> 86.3 | I2: =IF($C2>75,IF($C2<=80,$C2,""),"")
A3: 603986 | B3: 兆易创新 | C3: 86.3 | D3: 385 | E3: -0.11415525 | F3: 破位 | G3: 跌破 MA20，趋势破坏，暂不参与 | H3: =IF($C3>80,$C3,"") -> 86.3 | I3: =IF($C3>75,IF($C3<=80,$C3,""),"")
A4: 601899 | B4: 紫金矿业 | C4: 81.8 | D4: 34.5 | E4: 1.1730205 | F4: T1确认买点 | G4: 买点1：明日开盘买入（信号日收盘 34.10，止损-5%） | H4: =IF($C4>80,$C4,"") -> 81.8 | I4: =IF($C4>75,IF($C4<=80,$C4,""),"")
A5: 603061 | B5: 金海通 | C5: 81.4 | D5: 307.73 | E5: 5.0775114 | F5: 破位 | G5: 跌破 MA20，趋势破坏，暂不参与 | H5: =IF($C5>80,$C5,"") -> 81.4 | I5: =IF($C5>75,IF($C5<=80,$C5,""),"")
A6: 002653 | B6: 海思科 | C6: 79.6 | D6: 67.07 | E6: 4.6497113 | F6: 破位 | G6: 跌破 MA20，趋势破坏，暂不参与 | H6: =IF($C6>80,$C6,"") | I6: =IF($C6>75,IF($C6<=80,$C6,""),"") -> 79.6
A7: 001309 | B7: 德明利 | C7: 78.5 | D7: 388.25 | E7: 0.52040182 | F7: 破位 | G7: 跌破 MA20，趋势破坏，暂不参与 | H7: =IF($C7>80,$C7,"") | I7: =IF($C7>75,IF($C7<=80,$C7,""),"") -> 78.5
A8: 000975 | B8: 山金国际 | C8: 78.2 | D8: 25.46 | E8: 5.1197358 | F8: 多头持有 | G8: MA10(23.02)上方，回踩低吸/持有 | H8: =IF($C8>80,$C8,"") | I8: =IF($C8>75,IF($C8<=80,$C8,""),"") -> 78.2
A9: 300666 | B9: 江丰电子 | C9: 77.5 | D9: 238.62 | E9: 7.2931655 | F9: 空头 | G9: 均线未多头，观望 | H9: =IF($C9>80,$C9,"") | I9: =IF($C9>75,IF($C9<=80,$C9,""),"") -> 77.5
A10: 601869 | B10: 长飞光纤 | C10: 77.5 | D10: 328.25 | E10: 5.0736236 | F10: 破位 | G10: 跌破 MA20，趋势破坏，暂不参与 | H10: =IF($C10>80,$C10,"") | I10: =IF($C10>75,IF($C10<=80,$C10,""),"") -> 77.5
A11: 002297 | B11: 博云新材 | C11: 77.3 | D11: 18.72 | E11: 4.8152296 | F11: 空头 | G11: 均线未多头，观望 | H11: =IF($C11>80,$C11,"") | I11: =IF($C11>75,IF($C11<=80,$C11,""),"") -> 77.3
A12: 603256 | B12: 宏和科技 | C12: 77.3 | D12: 148.74 | E12: 7.6967634 | F12: 破位 | G12: 跌破 MA20，趋势破坏，暂不参与
A13: 002842 | B13: 翔鹭钨业 | C13: 76.4 | D13: 36.98 | E13: 7.0023148 | F13: 空头 | G13: 均线未多头，观望
A14: 600183 | B14: 生益科技 | C14: 76.2 | D14: 127.25 | E14: 3.6322176 | F14: 空头 | G14: 均线未多头，观望
A15: 600549 | B15: 厦门钨业 | C15: 76.2 | D15: 57.47 | E15: 6.9806404 | F15: 空头 | G15: 均线未多头，观望
A16: 003031 | B16: 中瓷电子 | C16: 76 | D16: 111.76 | E16: 2.8813403 | F16: 空头 | G16: 均线未多头，观望
A17: 301201 | B17: 诚达药业 | C17: 76 | D17: 33.24 | E17: 6.6067992 | F17: 空头 | G17: 均线未多头，观望
A18: 600489 | B18: 中金黄金 | C18: 75.6 | D18: 25.11 | E18: 3.5463918 | F18: 多头持有 | G18: MA10(22.51)上方，回踩低吸/持有
A19: 605305 | B19: 中际联合 | C19: 75.4 | D19: 40.1 | E19: 0.75376884 | F19: 空头 | G19: 均线未多头，观望
A20: 605499 | B20: 东鹏饮料 | C20: 74.8 | D20: 120.89 | E20: -1.3464991 | F20: 破位 | G20: 跌破 MA20，趋势破坏，暂不参与
A21: 600236 | B21: 桂冠电力 | C21: 74.5 | D21: 10.97 | E21: -1.4375562 | F21: 回踩低吸 | G21: 买点2：MA10(10.79)附近缩量企稳，可低吸
A22: 002192 | B22: 融捷股份 | C22: 74.3 | D22: 66.95 | E22: -0.90290112 | F22: 空头 | G22: 均线未多头，观望
A23: 600499 | B23: 科达制造 | C23: 73.6 | D23: 14.4 | E23: -0.82644628 | F23: 破位 | G23: 跌破 MA20，趋势破坏，暂不参与
A24: 603979 | B24: 金诚信 | C24: 73.6 | D24: 78.4 | E24: -0.35587189 | F24: T1确认买点 | G24: 买点1：明日开盘买入（信号日收盘 78.68，止损-5%）
A25: 600801 | B25: 华新水泥 | C25: 73 | D25: 23.01 | E25: 4.9247606 | F25: 多头持有 | G25: MA10(21.83)上方，回踩低吸/持有
A26: 002338 | B26: 奥普光电 | C26: 72.4 | D26: 42.17 | E26: 0.59637405 | F26: 空头 | G26: 均线未多头，观望
A27: 300540 | B27: 粤海饲料 | C27: 71.5 | D27: 33.61 | E27: 19.99286 | F27: 空头 | G27: 均线未多头，观望
A28: 603317 | B28: 天味食品 | C28: 71.5 | D28: 14.27 | E28: -3.7761295 | F28: 多头回踩 | G28: 回踩 MA10(14.46)→MA20(14.08)区间，观察企稳
A29: 000989 | B29: 九芝堂 | C29: 70.6 | D29: 9.05 | E29: -0.440044 | F29: 破位 | G29: 跌破 MA20，趋势破坏，暂不参与
A30: 300031 | B30: 宝通科技 | C30: 68.5 | D30: 21.32 | E30: -2.7372263 | F30: 空头 | G30: 均线未多头，观望
A31: 001339 | B31: 智微智能 | C31: 68 | D31: 83.54 | E31: 8.4794183 | F31: 空头 | G31: 均线未多头，观望
A32: 600520 | B32: 文一科技 | C32: 67.6 | D32: 23.95 | E32: 2.6575225 | F32: 破位 | G32: 跌破 MA20，趋势破坏，暂不参与
A33: 300191 | B33: 潜能恒信 | C33: 67.4 | D33: 32.45 | E33: 7.0957096 | F33: 多头持有 | G33: MA10(29.43)上方，回踩低吸/持有
A34: 002793 | B34: 罗欣药业 | C34: 64.4 | D34: 5.05 | E34: -0.59055118 | F34: 多头持有 | G34: MA10(4.82)上方，回踩低吸/持有
A35: 003032 | B35: 传智教育 | C35: 52 | D35: 10.95 | E35: -6.6496164 | F35: T1确认买点 | G35: 买点1：明日开盘买入（信号日收盘 11.73，止损-5%）（⚠10日已+96%，涨幅过大勿追）
A36: 300497 | B36: 富祥股份 | C36: 47.5 | D36: 18.25 | E36: 3.988604 | F36: 空头 | G36: 均线未多头，观望
A37: 002197 | B37: 证通电子 | C37: 44.5 | D37: 7.24 | E37: 0.8356546 | F37: 多头持有 | G37: MA10(6.84)上方，回踩低吸/持有

Sheet Data
A1: 日期 | B1: 类型 | C1: 代码 | D1: 名称 | E1: 综合分 | F1: 收盘 | G1: 涨跌幅(%) | H1: 状态 | I1: 提示 | J1: MA10 | K1: MA20 | L1: 量比 | M1: 10日涨幅(%) | N1: 买点序号
A2: 46238 | B2: 观察池 | C2: 000657 | D2: 中钨高新 | E2: 86.3 | F2: 52.21 | G2: 8.7934986 | H2: 破位 | I2: 跌破 MA20，趋势破坏，暂不参与 | J2: 53.499 | K2: 60.904 | L2: 1.332194 | M2: -13.61681
A3: 46238 | B3: 观察池 | C3: 603986 | D3: 兆易创新 | E3: 86.3 | F3: 356.02 | G3: 4.4843576 | H3: 破位 | I3: 跌破 MA20，趋势破坏，暂不参与 | J3: 401.411 | K3: 474.247 | L3: 0.82473114 | M3: -25.131958
A4: 46238 | B4: 观察池 | C4: 601899 | D4: 紫金矿业 | E4: 81.8 | F4: 32.12 | G4: -1.3210445 | H4: 回踩低吸 | I4: 买点2：MA10(32.27)附近缩量企稳，可低吸 | J4: 32.27 | K4: 30.391 | L4: 0.867759 | M4: 6.3224098
A5: 46238 | B5: 观察池 | C5: 603061 | D5: 金海通 | E5: 81.4 | F5: 266.24 | G5: 9.9983474 | H5: 破位 | I5: 跌破 MA20，趋势破坏，暂不参与 | J5: 277.883 | K5: 329.103 | L5: 0.64857145 | M5: -14.499502
A6: 46238 | B6: 观察池 | C6: 002653 | D6: 海思科 | E6: 79.6 | F6: 61.12 | G6: 3.7691002 | H6: 破位 | I6: 跌破 MA20，趋势破坏，暂不参与 | J6: 64.756 | K6: 67.758 | L6: 0.84802386 | M6: -14.577219
A7: 46238 | B7: 观察池 | C7: 001309 | D7: 德明利 | E7: 78.5 | F7: 364.18 | G7: 4.3495702 | H7: 破位 | I7: 跌破 MA20，趋势破坏，暂不参与 | J7: 389.883 | K7: 531.313 | L7: 0.85937794 | M7: -28.311024
A8: 46238 | B8: 观察池 | C8: 000975 | D8: 山金国际 | E8: 78.2 | F8: 22.56 | G8: -1.1826544 | H8: 回踩低吸 | I8: 买点2：MA10(22.59)附近缩量企稳，可低吸 | J8: 22.59 | K8: 21.034 | L8: 0.72505699 | M8: 10.210064
A9: 46238 | B9: 观察池 | C9: 300666 | D9: 江丰电子 | E9: 77.5 | F9: 200.08 | G9: 8.1455056 | H9: 破位 | I9: 跌破 MA20，趋势破坏，暂不参与 | J9: 216.144 | K9: 250.2945 | L9: 0.93800917 | M9: -15.492482
A10: 46238 | B10: 观察池 | C10: 601869 | D10: 长飞光纤 | E10: 77.5 | F10: 284 | G10: 8.2729699 | H10: 破位 | I10: 跌破 MA20，趋势破坏，暂不参与 | J10: 305.417 | K10: 353.9825 | L10: 1.0985505 | M10: -30.114671
A11: 46238 | B11: 观察池 | C11: 603256 | D11: 宏和科技 | E11: 77.3 | F11: 125.55 | G11: 8.8709677 | H11: 破位 | I11: 跌破 MA20，趋势破坏，暂不参与 | J11: 139.688 | K11: 162.351 | L11: 1.1774158 | M11: -20.878498
A12: 46238 | B12: 观察池 | C12: 002297 | D12: 博云新材 | E12: 77.3 | F12: 16.89 | G12: 7.2380952 | H12: 破位 | I12: 跌破 MA20，趋势破坏，暂不参与 | J12: 16.473 | K12: 18.713 | L12: 1.4426923 | M12: -4.7914318
A13: 46238 | B13: 观察池 | C13: 002842 | D13: 翔鹭钨业 | E13: 76.4 | F13: 31.42 | G13: 6.1486486 | H13: 破位 | I13: 跌破 MA20，趋势破坏，暂不参与 | J13: 30.502 | K13: 32.5275 | L13: 1.3844084 | M13: 0.93157726
A14: 46238 | B14: 观察池 | C14: 600549 | D14: 厦门钨业 | E14: 76.2 | F14: 49.38 | G14: 6.3765618 | H14: 破位 | I14: 跌破 MA20，趋势破坏，暂不参与 | J14: 48.063 | K14: 52.812 | L14: 1.3021262 | M14: -1.5942607
A15: 46238 | B15: 观察池 | C15: 600183 | D15: 生益科技 | E15: 76.2 | F15: 112.23 | G15: 9.9970597 | H15: 破位 | I15: 跌破 MA20，趋势破坏，暂不参与 | J15: 113.735 | K15: 128.1335 | L15: 0.86630005 | M15: -17.277217
A16: 46238 | B16: 观察池 | C16: 301201 | D16: 诚达药业 | E16: 76 | F16: 29.75 | G16: 5.4590571 | H16: 破位 | I16: 跌破 MA20，趋势破坏，暂不参与 | J16: 28.37 | K16: 32.1075 | L16: 1.1150676 | M16: -1.8799472
A17: 46238 | B17: 观察池 | C17: 003031 | D17: 中瓷电子 | E17: 76 | F17: 100.3 | G17: 10.002193 | H17: 破位 | I17: 跌破 MA20，趋势破坏，暂不参与 | J17: 100.677 | K17: 113.8125 | L17: 1.1901408 | M17: -8.8181818
A18: 46238 | B18: 观察池 | C18: 600489 | D18: 中金黄金 | E18: 75.6 | F18: 22.26 | G18: -1.242236 | H18: 回踩低吸 | I18: 买点2：MA10(22.02)附近缩量企稳，可低吸 | J18: 22.025 | K18: 21.002 | L18: 0.7736677 | M18: 7.1222329
A19: 46238 | B19: 观察池 | C19: 605305 | D19: 中际联合 | E19: 75.4 | F19: 39.65 | G19: 1.8756423 | H19: 空头 | I19: 均线未多头，观望 | J19: 38.996 | K19: 39.5895 | L19: 0.8017166 | M19: 4.0955631
A20: 46238 | B20: 观察池 | C20: 605499 | D20: 东鹏饮料 | E20: 74.8 | F20: 126.45 | G20: -2.4606603 | H20: 破位 | I20: 跌破 MA20，趋势破坏，暂不参与 | J20: 132.108 | K20: 128.526 | L20: 0.89363821 | M20: -3.3256881
A21: 46238 | B21: 观察池 | C21: 600236 | D21: 桂冠电力 | E21: 74.5 | F21: 11.08 | G21: 0.27149321 | H21: 空头 | I21: 均线未多头，观望 | J21: 10.936 | K21: 10.525 | L21: 0.85021487 | M21: -1.5111111
A22: 46238 | B22: 观察池 | C22: 002192 | D22: 融捷股份 | E22: 74.3 | F22: 64.21 | G22: 4.0849408 | H22: 破位 | I22: 跌破 MA20，趋势破坏，暂不参与 | J22: 63.147 | K22: 66.1205 | L22: 0.77198728 | M22: 10.26962
A23: 46238 | B23: 观察池 | C23: 600499 | D23: 科达制造 | E23: 73.6 | F23: 15.67 | G23: -1.5084852 | H23: 多头回踩 | I23: 回踩 MA10(15.85)→MA20(15.33)区间，观察企稳 | J23: 15.847 | K23: 15.3275 | L23: 1.0145438 | M23: 5.4508748
A24: 46238 | B24: 观察池 | C24: 603979 | D24: 金诚信 | E24: 73.6 | F24: 71.53 | G24: -0.041922862 | H24: 回踩低吸 | I24: 买点2：MA10(72.50)附近缩量企稳，可低吸 | J24: 72.502 | K24: 68.7075 | L24: 0.92087709 | M24: 7.8395899
A25: 46238 | B25: 观察池 | C25: 600801 | D25: 华新水泥 | E25: 73 | F25: 21.46 | G25: 1.2264151 | H25: 回踩低吸 | I25: 买点2：MA10(21.58)附近缩量企稳，可低吸 | J25: 21.581 | K25: 20.241 | L25: 0.86709126 | M25: 4.1747573
A26: 46238 | B26: 观察池 | C26: 002338 | D26: 奥普光电 | E26: 72.4 | F26: 39.91 | G26: 2.1238485 | H26: 破位 | I26: 跌破 MA20，趋势破坏，暂不参与 | J26: 39.654 | K26: 42.9475 | L26: 0.6222709 | M26: 0.45305814
A27: 46238 | B27: 观察池 | C27: 603317 | D27: 天味食品 | E27: 71.5 | F27: 14.93 | G27: 0.81026334 | H27: 多头持有 | I27: MA10(14.34)上方，回踩低吸/持有 | J27: 14.337 | K27: 14 | L27: 0.61642771 | M27: 8.1100652
A28: 46238 | B28: 观察池 | C28: 300540 | D28: 粤海饲料 | E28: 71.5 | F28: 26.25 | G28: 3.8370253 | H28: 破位 | I28: 跌破 MA20，趋势破坏，暂不参与 | J28: 27.926 | K28: 33.159 | L28: 0.7772544 | M28: -15.567707
A29: 46238 | B29: 观察池 | C29: 000989 | D29: 九芝堂 | E29: 70.6 | F29: 9.24 | G29: 0.65359477 | H29: 多头持有 | I29: MA10(9.06)上方，回踩低吸/持有 | J29: 9.057 | K29: 9.0075 | L29: 0.92347902 | M29: 3.7037037
A30: 46238 | B30: 观察池 | C30: 300031 | D30: 宝通科技 | E30: 68.5 | F30: 21.27 | G30: 8.7423313 | H30: 空头 | I30: 均线未多头，观望 | J30: 18.985 | K30: 19.8725 | L30: 1.6284414 | M30: 8.575804
A31: 46238 | B31: 观察池 | C31: 001339 | D31: 智微智能 | E31: 68 | F31: 71.97 | G31: 9.9954149 | H31: 破位 | I31: 跌破 MA20，趋势破坏，暂不参与 | J31: 71.062 | K31: 79.5905 | L31: 0.86642951 | M31: -8.9448381
A32: 46238 | B32: 观察池 | C32: 600520 | D32: 文一科技 | E32: 67.6 | F32: 22.29 | G32: 5.740038 | H32: 破位 | I32: 跌破 MA20，趋势破坏，暂不参与 | J32: 22.595 | K32: 26.53 | L32: 0.80990272 | M32: -9.9757674
A33: 46238 | B33: 观察池 | C33: 300191 | D33: 潜能恒信 | E33: 67.4 | F33: 29.47 | G33: 5.5515759 | H33: 空头 | I33: 均线未多头，观望 | J33: 29.172 | K33: 28.165 | L33: 1.0631766 | M33: 11.671088
A34: 46238 | B34: 观察池 | C34: 002793 | D34: 罗欣药业 | E34: 64.4 | F34: 5.12 | G34: 10.107527 | H34: 空头 | I34: 均线未多头，观望 | J34: 4.805 | K34: 4.7135 | L34: 1.2916491 | M34: 14.03118
A35: 46238 | B35: 观察池 | C35: 003032 | D35: 传智教育 | E35: 52 | F35: 10.66 | G35: 10.01032 | H35: T0新信号 | I35: 明日确认：收>8.89 且 低点≥10.34 → 后日开盘买入（⚠10日已+97%，涨幅过大勿追） | J35: 7.35 | K35: 6.334 | L35: 1.2307481 | M35: 96.678967
A36: 46238 | B36: 观察池 | C36: 300497 | D36: 富祥股份 | E36: 47.5 | F36: 16.5 | G36: 3.7735849 | H36: 破位 | I36: 跌破 MA20，趋势破坏，暂不参与 | J36: 16.858 | K36: 17.3145 | L36: 0.7664303 | M36: -2.7695934
A37: 46238 | B37: 观察池 | C37: 002197 | D37: 证通电子 | E37: 44.5 | F37: 7.22 | G37: 4.9418605 | H37: 空头 | I37: 均线未多头，观望 | J37: 6.861 | K37: 6.279 | L37: 1.0186382 | M37: 13.880126
A38: 46239 | B38: 观察池 | C38: 000657 | D38: 中钨高新 | E38: 86.3 | F38: 57.43 | G38: 9.9980847 | H38: 破位 | I38: 跌破 MA20，趋势破坏，暂不参与 | J38: 53.431 | K38: 60.078 | L38: 1.2796619 | M38: -1.1701945
A39: 46239 | B39: 观察池 | C39: 603986 | D39: 兆易创新 | E39: 86.3 | F39: 385.44 | G39: 8.2635807 | H39: 破位 | I39: 跌破 MA20，趋势破坏，暂不参与 | J39: 392.955 | K39: 463.3605 | L39: 0.86376497 | M39: -17.991489
A40: 46239 | B40: 观察池 | C40: 601899 | D40: 紫金矿业 | E40: 81.8 | F40: 34.1 | G40: 6.1643836 | H40: T0新信号 | I40: 明日确认：收>32.88 且 低点≥33.08 → 后日开盘买入 | J40: 32.46 | K40: 30.728 | L40: 1.7790805 | M40: 5.9006211
...
